<?xml version="1.0"?>

<robot name="robotiq_85_gripper">
  <!-- control -->
  <link name="base_link">
    <inertial>
      <mass value="0" />
      <inertia ixx = "0" ixy = "0" ixz = "0"
               iyx = "0" iyy = "0" iyz = "0"
               izx = "0" izy = "0" izz = "0" />
    </inertial>
  </link>

  <joint name="center_x" type="prismatic">
    <parent link="base_link"/>
    <child link="y_control"/>
    <axis xyz="1 0 0"/>
    <limit effort="1000.0" lower="-0.5" upper="0.5" velocity="0.2"/>
  </joint>

  <link name="y_control">
    <inertial>
      <mass value="0.1" />
      <inertia ixx = "0" ixy = "0" ixz = "0"
               iyx = "0" iyy = "0" iyz = "0"
               izx = "0" izy = "0" izz = "0" />
    </inertial>
  </link>

  <joint name="center_y" type="prismatic">
    <parent link="y_control"/>
    <child link="z_control"/>
    <axis xyz="0 1 0"/>
    <limit effort="1000.0" lower="-0.5" upper="0.5" velocity="0.2"/>
  </joint>

  <link name="z_control">
    <inertial>
      <mass value="0.1" />
      <inertia ixx = "0" ixy = "0" ixz = "0"
               iyx = "0" iyy = "0" iyz = "0"
               izx = "0" izy = "0" izz = "0" />
    </inertial>
  </link>

  <joint name="center_z" type="prismatic">
    <parent link="z_control"/>
    <child link="yaw_control"/>
    <axis xyz="0 0 1"/>
    <limit effort="1000.0" lower="-0.25" upper="1" velocity="0.2"/>
  </joint>

  <link name="yaw_control">
    <inertial>
      <mass value="0.1" />
      <inertia ixx = "0" ixy = "0" ixz = "0"
               iyx = "0" iyy = "0" iyz = "0"
               izx = "0" izy = "0" izz = "0" />
    </inertial>
  </link>

  <joint name="gripper_yaw" type="revolute">
    <parent link="yaw_control"/>
    <child link="pitch_control"/>
    <axis xyz="0 0 1"/>
    <limit lower="-31.4" upper="31.4" velocity="3.14" effort="10000"/>

  </joint>

  <link name="pitch_control">thetaList
    <inertial>
      <mass value="0.1" />
      <inertia ixx = "0" ixy = "0" ixz = "0"
               iyx = "0" iyy = "0" iyz = "0"
               izx = "0" izy = "0" izz = "0" />
    </inertial>
  </link>

  <joint name="gripper_pitch" type="revolute">
    <parent link="pitch_control"/>
    <child link="roll_control"/>
    <axis xyz="0 1 0"/>
    <limit lower="-31.4" upper="31.4" velocity="3.14" effort="10000"/>

  </joint>

  <link name="roll_control">
    <inertial>
      <mass value="0.1" />
      <inertia ixx = "0" ixy = "0" ixz = "0"
               iyx = "0" iyy = "0" iyz = "0"
               izx = "0" izy = "0" izz = "0" />
    </inertial>
  </link>

  <joint name="gripper_roll" type="revolute">
    <parent link="roll_control"/>
    <child link="dummy_center_indicator_link"/>
    <axis xyz="1 0 0"/>
    <limit lower="-31.4" upper="31.4" velocity="3.14" effort="100000"/>
  </joint>

  <link name="dummy_center_indicator_link">
    <visual>
      <geometry>
        <box size="0.085 0.002 0.020"/>
      </geometry>
    </visual>
    <inertial>
      <mass value="0.1" />
      <inertia ixx = "0" ixy = "0" ixz = "0"
               iyx = "0" iyy = "0" iyz = "0"
               izx = "0" izy = "0" izz = "0" />
    </inertial>
  </link>

  <joint name="dummy_center_fixed_joint" type="fixed">
    <parent link="dummy_center_indicator_link"/>
    <child link="box_base_link"/>
    <origin xyz="0.0 0.0 0.0691" />
  </joint>

  <!-- robot -->
    <link name="box_base_link">
      <visual>
        <geometry>
          <box size="0.075, 0.075, 0.090" />
        </geometry>
      </visual>
      <collision>
        <geometry>
          <box size="0.075, 0.075, 0.090" />
        </geometry>
      </collision>
      <inertial>
        <mass value="0.636951" />
        <origin xyz="0.0 0.0 0.0" />
        <inertia ixx = "0.000380" ixy = "0.000000" ixz = "0.000000"
             iyx = "0.000000" iyy = "0.001110" iyz = "0.000000"
             izx = "0.000000" izy = "0.000000" izz = "0.001171" />
      </inertial>
    </link>

    <joint name="box_left_joint" type="prismatic">
      <parent link="box_base_link"/>
      <child link="box_left_finger_link"/>
      <axis xyz="-1 0 0"/>
      <origin xyz="0.0575 0 -0.0691"/>
      <limit lower="0.0" upper="0.0415" velocity="3" effort="1000"/>
    </joint>

    <joint name="box_right_joint" type="prismatic">
      <parent link="box_base_link"/>
      <child link="box_right_finger_link"/>
      <axis xyz="1 0 0"/>
      <origin xyz="-0.0575 0 -0.0691"/>
      <limit lower="0" upper="0.0415" velocity="3" effort="1000"/>
    </joint>

    <link name="box_left_finger_link">
      <visual>
        <geometry>
          <box size="0.030, 0.022, 0.048" />
        </geometry>
      </visual>
      <collision>
        <geometry>
          <box size="0.030, 0.022, 0.048" />
        </geometry>
      </collision>
      <inertial>
        <mass value="0.018491" />
        <origin xyz="0.0 0.0 0.0" />
        <inertia ixx = "0.000009" ixy = "-0.000001" ixz = "0.000000"
             iyx = "-0.000001" iyy = "0.000001" iyz = "0.000000"
             izx = "0.000000" izy = "0.000000" izz = "0.000010" />
      </inertial>
    </link>

    <link name="box_right_finger_link">
      <visual>
        <geometry>
          <box size="0.030, 0.022, 0.048" />
        </geometry>
      </visual>
      <collision>
        <geometry>
          <box size="0.030, 0.022, 0.048" />
        </geometry>
      </collision>
      <inertial>
        <mass value="0.018491" />
        <origin xyz="0.0 0.0 0.0" />
        <inertia ixx = "0.000009" ixy = "-0.000001" ixz = "0.000000"
             iyx = "-0.000001" iyy = "0.000001" iyz = "0.000000"
             izx = "0.000000" izy = "0.000000" izz = "0.000010" />
      </inertial>
    </link>
</robot>